Fix case where `PyErr::matches` and `PyErr::is_instance` returned results inconsistent with `PyErr::get_type`.
