`Err` returned from `#[pyfunction]` will now have a non-None `__context__` if called from inside a `catch` block.
